Workbook

Sheet Old Bow v2
A1: Player | B1: Trophies | C1: MVPs | D1: 4 Piece | E1: 5 Piece | F1: 6 Piece | G1: 7 Piece | H1: Kills | I1: Avg. Kills | J1: Median Kills | K1: Highest Single Game Kills | L1: Match Wins | M1: Match Losses | N1: Match % | O1: Map Wins | P1: Map Losses | Q1: Map % | R1: Round Wins | S1: Round Losses | T1: Round % | U1: Airport 1 | V1: Airport 2 | W1: Carnival | X1: Close Quarters | Y1: CSL | Z1: Garage | AA1: Import / Export | AB1: Meat Factory | AC1: Old City | AD1: Parkade | AE1: Peaks | AF1: Presidio | AG1: Scharins | AH1: Training | AI1: Trainyard | AJ1: Warehouse
A2: 10thLetter | B2: - | C2: - | H2: =SUMIFS('OB History'!C:C,'OB History'!B:B,A2) -> 2 | I2: =AVERAGEIFS('OB History'!C:C,'OB History'!B:B,A2) -> 2 | J2: {=MEDIAN(IF('OB History'!B:B=A2, 'OB History'!C:C))} -> 2 | K2: {=MAX(IF('OB History'!B:B=A2, 'OB History'!C:C))} -> 2 | L2: =COUNTIFS('OB History'!B:B,A2,'OB History'!D:D, 1) -> 1 | M2: =COUNTIFS('OB History'!B:B,A2,'OB History'!D:D, 0) -> 0 | N2: =LOOKUP(2, 1/('OB History'!$B:$B=A2), 'OB History'!$AD:$AD) -> 1 | O2: =SUMIFS('OB History'!F:F,'OB History'!B:B,A2) -> 3 | P2: =SUMIFS('OB History'!E:E,'OB History'!B:B,A2)-O2 -> 2 | Q2: =LOOKUP(2, 1/('OB History'!$B:$B=A2), 'OB History'!$AB:$AB) -> 0.6 | R2: =SUMIFS('OB History'!H:H,'OB History'!B:B,A2) -> 14 | S2: =SUMIFS('OB History'!G:G,'OB History'!B:B,A2)-R2 -> 6 | T2: =LOOKUP(2, 1/('OB History'!$B:$B=A2), 'OB History'!$AC:$AC) -> 0.7 | U2: =COUNTIFS('OB History'!$B:$B,$A$2,'OB History'!K:K, 1) -> 0 | V2: =COUNTIFS('OB History'!$B:$B,$A$2,'OB History'!L:L, 1) -> 0 | W2: =COUNTIFS('OB History'!$B:$B,$A$2,'OB History'!M:M, 1) -> 0 | X2: =COUNTIFS('OB History'!$B:$B,$A$2,'OB History'!N:N, 1) -> 1 | Y2: =COUNTIFS('OB History'!$B:$B,$A$2,'OB History'!O:O, 1) -> 0 | Z2: =COUNTIFS('OB History'!$B:$B,$A$2,'OB History'!P:P, 1) -> 0 | AA2: =COUNTIFS('OB History'!$B:$B,$A$2,'OB History'!Q:Q, 1) -> 0 | AB2: =COUNTIFS('OB History'!$B:$B,$A$2,'OB History'!R:R, 1) -> 0 | AC2: =COUNTIFS('OB History'!$B:$B,$A$2,'OB History'!S:S, 1) -> 0 | AD2: =COUNTIFS('OB History'!$B:$B,$A$2,'OB History'!T:T, 1) -> 0 | AE2: =COUNTIFS('OB History'!$B:$B,$A$2,'OB History'!U:U, 1) -> 0 | AF2: =COUNTIFS('OB History'!$B:$B,$A$2,'OB History'!V:V, 1) -> 0 | AG2: =COUNTIFS('OB History'!$B:$B,$A$2,'OB History'!W:W, 1) -> 0 | AH2: =COUNTIFS('OB History'!$B:$B,$A$2,'OB History'!X:X, 1) -> 1 | AI2: =COUNTIFS('OB History'!$B:$B,$A$2,'OB History'!Y:Y, 1) -> 0 | AJ2: =COUNTIFS('OB History'!$B:$B,$A$2,'OB History'!Z:Z, 1) -> 1
A3: AftaShock | B3: 🏆 | C3: - | D3: 1 | H3: =SUMIFS('OB History'!C:C,'OB History'!B:B,A3) -> 395 | I3: =AVERAGEIFS('OB History'!C:C,'OB History'!B:B,A3) -> 11.969697 | J3: {=MEDIAN(IF('OB History'!B:B=A3, 'OB History'!C:C))} -> 10 | K3: {=MAX(IF('OB History'!B:B=A3, 'OB History'!C:C))} -> 35 | L3: =COUNTIFS('OB History'!B:B,A3,'OB History'!D:D, 1) -> 16 | M3: =COUNTIFS('OB History'!B:B,A3,'OB History'!D:D, 0) -> 17 | N3: =LOOKUP(2, 1/('OB History'!$B:$B=A3), 'OB History'!$AD:$AD) -> 0.48484848 | O3: =SUMIFS('OB History'!F:F,'OB History'!B:B,A3) -> 61 | P3: =SUMIFS('OB History'!E:E,'OB History'!B:B,A3)-O3 -> 69 | Q3: =LOOKUP(2, 1/('OB History'!$B:$B=A3), 'OB History'!$AB:$AB) -> 0.4530303 | R3: =SUMIFS('OB History'!H:H,'OB History'!B:B,A3) -> 262 | S3: =SUMIFS('OB History'!G:G,'OB History'!B:B,A3)-R3 -> 280 | T3: =LOOKUP(2, 1/('OB History'!$B:$B=A3), 'OB History'!$AC:$AC) -> 0.47454545 | U3: =COUNTIFS('OB History'!$B:$B,$A$3,'OB History'!K:K, 1) -> 4 | V3: =COUNTIFS('OB History'!$B:$B,$A$3,'OB History'!L:L, 1) -> 7 | W3: =COUNTIFS('OB History'!$B:$B,$A$3,'OB History'!M:M, 1) -> 4 | X3: =COUNTIFS('OB History'!$B:$B,$A$3,'OB History'!N:N, 1) -> 10 | Y3: =COUNTIFS('OB History'!$B:$B,$A$3,'OB History'!O:O, 1) -> 1 | Z3: =COUNTIFS('OB History'!$B:$B,$A$3,'OB History'!P:P, 1) -> 3 | AA3: =COUNTIFS('OB History'!$B:$B,$A$3,'OB History'!Q:Q, 1) -> 1 | AB3: =COUNTIFS('OB History'!$B:$B,$A$3,'OB History'!R:R, 1) -> 2 | AC3: =COUNTIFS('OB History'!$B:$B,$A$3,'OB History'!S:S, 1) -> 1 | AD3: =COUNTIFS('OB History'!$B:$B,$A$3,'OB History'!T:T, 1) -> 0 | AE3: =COUNTIFS('OB History'!$B:$B,$A$3,'OB History'!U:U, 1) -> 1 | AF3: =COUNTIFS('OB History'!$B:$B,$A$3,'OB History'!V:V, 1) -> 1 | AG3: =COUNTIFS('OB History'!$B:$B,$A$3,'OB History'!W:W, 1) -> 2 | AH3: =COUNTIFS('OB History'!$B:$B,$A$3,'OB History'!X:X, 1) -> 6 | AI3: =COUNTIFS('OB History'!$B:$B,$A$3,'OB History'!Y:Y, 1) -> 8 | AJ3: =COUNTIFS('OB History'!$B:$B,$A$3,'OB History'!Z:Z, 1) -> 10
A4: Agile | B4: - | C4: - | D4: 1 | H4: =SUMIFS('OB History'!C:C,'OB History'!B:B,A4) -> 622 | I4: =AVERAGEIFS('OB History'!C:C,'OB History'!B:B,A4) -> 11.107143 | J4: {=MEDIAN(IF('OB History'!B:B=A4, 'OB History'!C:C))} -> 11 | K4: {=MAX(IF('OB History'!B:B=A4, 'OB History'!C:C))} -> 25 | L4: =COUNTIFS('OB History'!B:B,A4,'OB History'!D:D, 1) -> 26 | M4: =COUNTIFS('OB History'!B:B,A4,'OB History'!D:D, 0) -> 30 | N4: =LOOKUP(2, 1/('OB History'!$B:$B=A4), 'OB History'!$AD:$AD) -> 0.46428571 | O4: =SUMIFS('OB History'!F:F,'OB History'!B:B,A4) -> 112 | P4: =SUMIFS('OB History'!E:E,'OB History'!B:B,A4)-O4 -> 116 | Q4: =LOOKUP(2, 1/('OB History'!$B:$B=A4), 'OB History'!$AB:$AB) -> 0.5 | R4: =SUMIFS('OB History'!H:H,'OB History'!B:B,A4) -> 470 | S4: =SUMIFS('OB History'!G:G,'OB History'!B:B,A4)-R4 -> 482 | T4: =LOOKUP(2, 1/('OB History'!$B:$B=A4), 'OB History'!$AC:$AC) -> 0.5 | U4: =COUNTIFS('OB History'!$B:$B,$A$4,'OB History'!K:K, 1) -> 9 | V4: =COUNTIFS('OB History'!$B:$B,$A$4,'OB History'!L:L, 1) -> 7 | W4: =COUNTIFS('OB History'!$B:$B,$A$4,'OB History'!M:M, 1) -> 4 | X4: =COUNTIFS('OB History'!$B:$B,$A$4,'OB History'!N:N, 1) -> 14 | Y4: =COUNTIFS('OB History'!$B:$B,$A$4,'OB History'!O:O, 1) -> 1 | Z4: =COUNTIFS('OB History'!$B:$B,$A$4,'OB History'!P:P, 1) -> 7 | AA4: =COUNTIFS('OB History'!$B:$B,$A$4,'OB History'!Q:Q, 1) -> 4 | AB4: =COUNTIFS('OB History'!$B:$B,$A$4,'OB History'!R:R, 1) -> 6 | AC4: =COUNTIFS('OB History'!$B:$B,$A$4,'OB History'!S:S, 1) -> 2 | AD4: =COUNTIFS('OB History'!$B:$B,$A$4,'OB History'!T:T, 1) -> 1 | AE4: =COUNTIFS('OB History'!$B:$B,$A$4,'OB History'!U:U, 1) -> 0 | AF4: =COUNTIFS('OB History'!$B:$B,$A$4,'OB History'!V:V, 1) -> 2 | AG4: =COUNTIFS('OB History'!$B:$B,$A$4,'OB History'!W:W, 1) -> 10 | AH4: =COUNTIFS('OB History'!$B:$B,$A$4,'OB History'!X:X, 1) -> 15 | AI4: =COUNTIFS('OB History'!$B:$B,$A$4,'OB History'!Y:Y, 1) -> 18 | AJ4: =COUNTIFS('OB History'!$B:$B,$A$4,'OB History'!Z:Z, 1) -> 12
A5: AJ | B5: - | C5: - | D5: 7 | E5: 1 | H5: =SUMIFS('OB History'!C:C,'OB History'!B:B,A5) -> 1211 | I5: =AVERAGEIFS('OB History'!C:C,'OB History'!B:B,A5) -> 19.532258 | J5: {=MEDIAN(IF('OB History'!B:B=A5, 'OB History'!C:C))} -> 19 | K5: {=MAX(IF('OB History'!B:B=A5, 'OB History'!C:C))} -> 36 | L5: =COUNTIFS('OB History'!B:B,A5,'OB History'!D:D, 1) -> 31 | M5: =COUNTIFS('OB History'!B:B,A5,'OB History'!D:D, 0) -> 31 | N5: =LOOKUP(2, 1/('OB History'!$B:$B=A5), 'OB History'!$AD:$AD) -> 0.5 | O5: =SUMIFS('OB History'!F:F,'OB History'!B:B,A5) -> 119 | P5: =SUMIFS('OB History'!E:E,'OB History'!B:B,A5)-O5 -> 128 | Q5: =LOOKUP(2, 1/('OB History'!$B:$B=A5), 'OB History'!$AB:$AB) -> 0.47548387 | R5: =SUMIFS('OB History'!H:H,'OB History'!B:B,A5) -> 490 | S5: =SUMIFS('OB History'!G:G,'OB History'!B:B,A5)-R5 -> 518 | T5: =LOOKUP(2, 1/('OB History'!$B:$B=A5), 'OB History'!$AC:$AC) -> 0.48274194 | U5: =COUNTIFS('OB History'!$B:$B,$A$5,'OB History'!K:K, 1) -> 10 | V5: =COUNTIFS('OB History'!$B:$B,$A$5,'OB History'!L:L, 1) -> 8 | W5: =COUNTIFS('OB History'!$B:$B,$A$5,'OB History'!M:M, 1) -> 4 | X5: =COUNTIFS('OB History'!$B:$B,$A$5,'OB History'!N:N, 1) -> 14 | Y5: =COUNTIFS('OB History'!$B:$B,$A$5,'OB History'!O:O, 1) -> 5 | Z5: =COUNTIFS('OB History'!$B:$B,$A$5,'OB History'!P:P, 1) -> 9 | AA5: =COUNTIFS('OB History'!$B:$B,$A$5,'OB History'!Q:Q, 1) -> 1 | AB5: =COUNTIFS('OB History'!$B:$B,$A$5,'OB History'!R:R, 1) -> 4 | AC5: =COUNTIFS('OB History'!$B:$B,$A$5,'OB History'!S:S, 1) -> 1 | AD5: =COUNTIFS('OB History'!$B:$B,$A$5,'OB History'!T:T, 1) -> 3 | AE5: =COUNTIFS('OB History'!$B:$B,$A$5,'OB History'!U:U, 1) -> 0 | AF5: =COUNTIFS('OB History'!$B:$B,$A$5,'OB History'!V:V, 1) -> 1 | AG5: =COUNTIFS('OB History'!$B:$B,$A$5,'OB History'!W:W, 1) -> 4 | AH5: =COUNTIFS('OB History'!$B:$B,$A$5,'OB History'!X:X, 1) -> 16 | AI5: =COUNTIFS('OB History'!$B:$B,$A$5,'OB History'!Y:Y, 1) -> 15 | AJ5: =COUNTIFS('OB History'!$B:$B,$A$5,'OB History'!Z:Z, 1) -> 24
A6: Bearded | B6: - | C6: - | D6: 1 | H6: =SUMIFS('OB History'!C:C,'OB History'!B:B,A6) -> 125 | I6: =AVERAGEIFS('OB History'!C:C,'OB History'!B:B,A6) -> 10.416667 | J6: {=MEDIAN(IF('OB History'!B:B=A6, 'OB History'!C:C))} -> 10.5 | K6: {=MAX(IF('OB History'!B:B=A6, 'OB History'!C:C))} -> 19 | L6: =COUNTIFS('OB History'!B:B,A6,'OB History'!D:D, 1) -> 6 | M6: =COUNTIFS('OB History'!B:B,A6,'OB History'!D:D, 0) -> 6 | N6: =LOOKUP(2, 1/('OB History'!$B:$B=A6), 'OB History'!$AD:$AD) -> 0.5 | O6: =SUMIFS('OB History'!F:F,'OB History'!B:B,A6) -> 28 | P6: =SUMIFS('OB History'!E:E,'OB History'!B:B,A6)-O6 -> 25 | Q6: =LOOKUP(2, 1/('OB History'!$B:$B=A6), 'OB History'!$AB:$AB) -> 0.54583333 | R6: =SUMIFS('OB History'!H:H,'OB History'!B:B,A6) -> 117 | S6: =SUMIFS('OB History'!G:G,'OB History'!B:B,A6)-R6 -> 104 | T6: =LOOKUP(2, 1/('OB History'!$B:$B=A6), 'OB History'!$AC:$AC) -> 0.54166667 | U6: =COUNTIFS('OB History'!$B:$B,$A$6,'OB History'!K:K, 1) -> 3 | V6: =COUNTIFS('OB History'!$B:$B,$A$6,'OB History'!L:L, 1) -> 2 | W6: =COUNTIFS('OB History'!$B:$B,$A$6,'OB History'!M:M, 1) -> 0 | X6: =COUNTIFS('OB History'!$B:$B,$A$6,'OB History'!N:N, 1) -> 4 | Y6: =COUNTIFS('OB History'!$B:$B,$A$6,'OB History'!O:O, 1) -> 0 | Z6: =COUNTIFS('OB History'!$B:$B,$A$6,'OB History'!P:P, 1) -> 1 | AA6: =COUNTIFS('OB History'!$B:$B,$A$6,'OB History'!Q:Q, 1) -> 0 | AB6: =COUNTIFS('OB History'!$B:$B,$A$6,'OB History'!R:R, 1) -> 2 | AC6: =COUNTIFS('OB History'!$B:$B,$A$6,'OB History'!S:S, 1) -> 0 | AD6: =COUNTIFS('OB History'!$B:$B,$A$6,'OB History'!T:T, 1) -> 0 | AE6: =COUNTIFS('OB History'!$B:$B,$A$6,'OB History'!U:U, 1) -> 0 | AF6: =COUNTIFS('OB History'!$B:$B,$A$6,'OB History'!V:V, 1) -> 0 | AG6: =COUNTIFS('OB History'!$B:$B,$A$6,'OB History'!W:W, 1) -> 3 | AH6: =COUNTIFS('OB History'!$B:$B,$A$6,'OB History'!X:X, 1) -> 4 | AI6: =COUNTIFS('OB History'!$B:$B,$A$6,'OB History'!Y:Y, 1) -> 4 | AJ6: =COUNTIFS('OB History'!$B:$B,$A$6,'OB History'!Z:Z, 1) -> 4
A7: BelievedKiller | B7: - | C7: - | H7: =SUMIFS('OB History'!C:C,'OB History'!B:B,A7) -> 10 | I7: =AVERAGEIFS('OB History'!C:C,'OB History'!B:B,A7) -> 5 | J7: {=MEDIAN(IF('OB History'!B:B=A7, 'OB History'!C:C))} -> 5 | K7: {=MAX(IF('OB History'!B:B=A7, 'OB History'!C:C))} -> 5 | L7: =COUNTIFS('OB History'!B:B,A7,'OB History'!D:D, 1) -> 0 | M7: =COUNTIFS('OB History'!B:B,A7,'OB History'!D:D, 0) -> 2 | N7: =LOOKUP(2, 1/('OB History'!$B:$B=A7), 'OB History'!$AD:$AD) -> 0 | O7: =SUMIFS('OB History'!F:F,'OB History'!B:B,A7) -> 3 | P7: =SUMIFS('OB History'!E:E,'OB History'!B:B,A7)-O7 -> 6 | Q7: =LOOKUP(2, 1/('OB History'!$B:$B=A7), 'OB History'!$AB:$AB) -> 0.325 | R7: =SUMIFS('OB History'!H:H,'OB History'!B:B,A7) -> 14 | S7: =SUMIFS('OB History'!G:G,'OB History'!B:B,A7)-R7 -> 22 | T7: =LOOKUP(2, 1/('OB History'!$B:$B=A7), 'OB History'!$AC:$AC) -> 0.39 | U7: =COUNTIFS('OB History'!$B:$B,$A$7,'OB History'!K:K, 1) -> 0 | V7: =COUNTIFS('OB History'!$B:$B,$A$7,'OB History'!L:L, 1) -> 0 | W7: =COUNTIFS('OB History'!$B:$B,$A$7,'OB History'!M:M, 1) -> 0 | X7: =COUNTIFS('OB History'!$B:$B,$A$7,'OB History'!N:N, 1) -> 0 | Y7: =COUNTIFS('OB History'!$B:$B,$A$7,'OB History'!O:O, 1) -> 1 | Z7: =COUNTIFS('OB History'!$B:$B,$A$7,'OB History'!P:P, 1) -> 0 | AA7: =COUNTIFS('OB History'!$B:$B,$A$7,'OB History'!Q:Q, 1) -> 0 | AB7: =COUNTIFS('OB History'!$B:$B,$A$7,'OB History'!R:R, 1) -> 1 | AC7: =COUNTIFS('OB History'!$B:$B,$A$7,'OB History'!S:S, 1) -> 0 | AD7: =COUNTIFS('OB History'!$B:$B,$A$7,'OB History'!T:T, 1) -> 0 | AE7: =COUNTIFS('OB History'!$B:$B,$A$7,'OB History'!U:U, 1) -> 0 | AF7: =COUNTIFS('OB History'!$B:$B,$A$7,'OB History'!V:V, 1) -> 0 | AG7: =COUNTIFS('OB History'!$B:$B,$A$7,'OB History'!W:W, 1) -> 0 | AH7: =COUNTIFS('OB History'!$B:$B,$A$7,'OB History'!X:X, 1) -> 0 | AI7: =COUNTIFS('OB History'!$B:$B,$A$7,'OB History'!Y:Y, 1) -> 1 | AJ7: =COUNTIFS('OB History'!$B:$B,$A$7,'OB History'!Z:Z, 1) -> 0
A8: Broken | B8: 🏆 | C8: 👑 | D8: 3 | E8: 2 | H8: =SUMIFS('OB History'!C:C,'OB History'!B:B,A8) -> 668 | I8: =AVERAGEIFS('OB History'!C:C,'OB History'!B:B,A8) -> 19.647059 | J8: {=MEDIAN(IF('OB History'!B:B=A8, 'OB History'!C:C))} -> 19 | K8: {=MAX(IF('OB History'!B:B=A8, 'OB History'!C:C))} -> 37 | L8: =COUNTIFS('OB History'!B:B,A8,'OB History'!D:D, 1) -> 24 | M8: =COUNTIFS('OB History'!B:B,A8,'OB History'!D:D, 0) -> 10 | N8: =LOOKUP(2, 1/('OB History'!$B:$B=A8), 'OB History'!$AD:$AD) -> 0.70588235 | O8: =SUMIFS('OB History'!F:F,'OB History'!B:B,A8) -> 84 | P8: =SUMIFS('OB History'!E:E,'OB History'!B:B,A8)-O8 -> 58 | Q8: =LOOKUP(2, 1/('OB History'!$B:$B=A8), 'OB History'!$AB:$AB) -> 0.59911765 | R8: =SUMIFS('OB History'!H:H,'OB History'!B:B,A8) -> 314 | S8: =SUMIFS('OB History'!G:G,'OB History'!B:B,A8)-R8 -> 272 | T8: =LOOKUP(2, 1/('OB History'!$B:$B=A8), 'OB History'!$AC:$AC) -> 0.54529412 | U8: =COUNTIFS('OB History'!$B:$B,$A$8,'OB History'!K:K, 1) -> 9 | V8: =COUNTIFS('OB History'!$B:$B,$A$8,'OB History'!L:L, 1) -> 9 | W8: =COUNTIFS('OB History'!$B:$B,$A$8,'OB History'!M:M, 1) -> 4 | X8: =COUNTIFS('OB History'!$B:$B,$A$8,'OB History'!N:N, 1) -> 5 | Y8: =COUNTIFS('OB History'!$B:$B,$A$8,'OB History'!O:O, 1) -> 7 | Z8: =COUNTIFS('OB History'!$B:$B,$A$8,'OB History'!P:P, 1) -> 4 | AA8: =COUNTIFS('OB History'!$B:$B,$A$8,'OB History'!Q:Q, 1) -> 1 | AB8: =COUNTIFS('OB History'!$B:$B,$A$8,'OB History'!R:R, 1) -> 3 | AC8: =COUNTIFS('OB History'!$B:$B,$A$8,'OB History'!S:S, 1) -> 0 | AD8: =COUNTIFS('OB History'!$B:$B,$A$8,'OB History'!T:T, 1) -> 1 | AE8: =COUNTIFS('OB History'!$B:$B,$A$8,'OB History'!U:U, 1) -> 1 | AF8: =COUNTIFS('OB History'!$B:$B,$A$8,'OB History'!V:V, 1) -> 1 | AG8: =COUNTIFS('OB History'!$B:$B,$A$8,'OB History'!W:W, 1) -> 3 | AH8: =COUNTIFS('OB History'!$B:$B,$A$8,'OB History'!X:X, 1) -> 11 | AI8: =COUNTIFS('OB History'!$B:$B,$A$8,'OB History'!Y:Y, 1) -> 12 | AJ8: =COUNTIFS('OB History'!$B:$B,$A$8,'OB History'!Z:Z, 1) -> 10
A9: Budden | B9: - | C9: - | H9: =SUMIFS('OB History'!C:C,'OB History'!B:B,A9) -> 192 | I9: =AVERAGEIFS('OB History'!C:C,'OB History'!B:B,A9) -> 12 | J9: {=MEDIAN(IF('OB History'!B:B=A9, 'OB History'!C:C))} -> 11.5 | K9: {=MAX(IF('OB History'!B:B=A9, 'OB History'!C:C))} -> 21 | L9: =COUNTIFS('OB History'!B:B,A9,'OB History'!D:D, 1) -> 8 | M9: =COUNTIFS('OB History'!B:B,A9,'OB History'!D:D, 0) -> 8 | N9: =LOOKUP(2, 1/('OB History'!$B:$B=A9), 'OB History'!$AD:$AD) -> 0.5 | O9: =SUMIFS('OB History'!F:F,'OB History'!B:B,A9) -> 34 | P9: =SUMIFS('OB History'!E:E,'OB History'!B:B,A9)-O9 -> 30 | Q9: =LOOKUP(2, 1/('OB History'!$B:$B=A9), 'OB History'!$AB:$AB) -> 0.55 | R9: =SUMIFS('OB History'!H:H,'OB History'!B:B,'Old Bow v2'!A9) -> 145 | S9: =SUMIFS('OB History'!G:G,'OB History'!B:B,'Old Bow v2'!A9)-R9 -> 128 | T9: =LOOKUP(2, 1/('OB History'!$B:$B=A9), 'OB History'!$AC:$AC) -> 0.5525 | U9: =COUNTIFS('OB History'!$B:$B,$A$9,'OB History'!K:K, 1) -> 2 | V9: =COUNTIFS('OB History'!$B:$B,$A$9,'OB History'!L:L, 1) -> 7 | W9: =COUNTIFS('OB History'!$B:$B,$A$9,'OB History'!M:M, 1) -> 0 | X9: =COUNTIFS('OB History'!$B:$B,$A$9,'OB History'!N:N, 1) -> 4 | Y9: =COUNTIFS('OB History'!$B:$B,$A$9,'OB History'!O:O, 1) -> 2 | Z9: =COUNTIFS('OB History'!$B:$B,$A$9,'OB History'!P:P, 1) -> 2 | AA9: =COUNTIFS('OB History'!$B:$B,$A$9,'OB History'!Q:Q, 1) -> 1 | AB9: =COUNTIFS('OB History'!$B:$B,$A$9,'OB History'!R:R, 1) -> 2 | AC9: =COUNTIFS('OB History'!$B:$B,$A$9,'OB History'!S:S, 1) -> 0 | AD9: =COUNTIFS('OB History'!$B:$B,$A$9,'OB History'!T:T, 1) -> 0 | AE9: =COUNTIFS('OB History'!$B:$B,$A$9,'OB History'!U:U, 1) -> 0 | AF9: =COUNTIFS('OB History'!$B:$B,$A$9,'OB History'!V:V, 1) -> 0 | AG9: =COUNTIFS('OB History'!$B:$B,$A$9,'OB History'!W:W, 1) -> 1 | AH9: =COUNTIFS('OB History'!$B:$B,$A$9,'OB History'!X:X, 1) -> 5 | AI9: =COUNTIFS('OB History'!$B:$B,$A$9,'OB History'!Y:Y, 1) -> 5 | AJ9: =COUNTIFS('OB History'!$B:$B,$A$9,'OB History'!Z:Z, 1) -> 3
A10: Cajun | B10: 🏆🏆 | C10: - | H10: =SUMIFS('OB History'!C:C,'OB History'!B:B,A10) -> 734 | I10: =AVERAGEIFS('OB History'!C:C,'OB History'!B:B,A10) -> 12.032787 | J10: {=MEDIAN(IF('OB History'!B:B=A10, 'OB History'!C:C))} -> 12 | K10: {=MAX(IF('OB History'!B:B=A10, 'OB History'!C:C))} -> 32 | L10: =COUNTIFS('OB History'!B:B,A10,'OB History'!D:D, 1) -> 33 | M10: =COUNTIFS('OB History'!B:B,A10,'OB History'!D:D, 0) -> 28 | N10: =LOOKUP(2, 1/('OB History'!$B:$B=A10), 'OB History'!$AD:$AD) -> 0.54098361 | O10: =SUMIFS('OB History'!F:F,'OB History'!B:B,A10) -> 124 | P10: =SUMIFS('OB History'!E:E,'OB History'!B:B,A10)-O10 -> 124 | Q10: =LOOKUP(2, 1/('OB History'!$B:$B=A10), 'OB History'!$AB:$AB) -> 0.48852459 | R10: =SUMIFS('OB History'!H:H,'OB History'!B:B,'Old Bow v2'!A10) -> 512 | S10: =SUMIFS('OB History'!G:G,'OB History'!B:B,'Old Bow v2'!A10)-R10 -> 508 | T10: =LOOKUP(2, 1/('OB History'!$B:$B=A10), 'OB History'!$AC:$AC) -> 0.4957377 | U10: =COUNTIFS('OB History'!$B:$B,$A$10,'OB History'!K:K, 1) -> 11 | V10: =COUNTIFS('OB History'!$B:$B,$A$10,'OB History'!L:L, 1) -> 9 | W10: =COUNTIFS('OB History'!$B:$B,$A$10,'OB History'!M:M, 1) -> 3 | X10: =COUNTIFS('OB History'!$B:$B,$A$10,'OB History'!N:N, 1) -> 19 | Y10: =COUNTIFS('OB History'!$B:$B,$A$10,'OB History'!O:O, 1) -> 6 | Z10: =COUNTIFS('OB History'!$B:$B,$A$10,'OB History'!P:P, 1) -> 10 | AA10: =COUNTIFS('OB History'!$B:$B,$A$10,'OB History'!Q:Q, 1) -> 0 | AB10: =COUNTIFS('OB History'!$B:$B,$A$10,'OB History'!R:R, 1) -> 3 | AC10: =COUNTIFS('OB History'!$B:$B,$A$10,'OB History'!S:S, 1) -> 2 | AD10: =COUNTIFS('OB History'!$B:$B,$A$10,'OB History'!T:T, 1) -> 1 | AE10: =COUNTIFS('OB History'!$B:$B,$A$10,'OB History'!U:U, 1) -> 0 | AF10: =COUNTIFS('OB History'!$B:$B,$A$10,'OB History'!V:V, 1) -> 0 | AG10: =COUNTIFS('OB History'!$B:$B,$A$10,'OB History'!W:W, 1) -> 12 | AH10: =COUNTIFS('OB History'!$B:$B,$A$10,'OB History'!X:X, 1) -> 21 | AI10: =COUNTIFS('OB History'!$B:$B,$A$10,'OB History'!Y:Y, 1) -> 9 | AJ10: =COUNTIFS('OB History'!$B:$B,$A$10,'OB History'!Z:Z, 1) -> 18
A11: Carnage | B11: - | C11: - | D11: 1 | E11: 1 | H11: =SUMIFS('OB History'!C:C,'OB History'!B:B,A11) -> 1035 | I11: =AVERAGEIFS('OB History'!C:C,'OB History'!B:B,A11) -> 11.896552 | J11: {=MEDIAN(IF('OB History'!B:B=A11, 'OB History'!C:C))} -> 11 | K11: {=MAX(IF('OB History'!B:B=A11, 'OB History'!C:C))} -> 26 | L11: =COUNTIFS('OB History'!B:B,A11,'OB History'!D:D, 1) -> 39 | M11: =COUNTIFS('OB History'!B:B,A11,'OB History'!D:D, 0) -> 48 | N11: =LOOKUP(2, 1/('OB History'!$B:$B=A11), 'OB History'!$AD:$AD) -> 0.44827586 | O11: =SUMIFS('OB History'!F:F,'OB History'!B:B,A11) -> 176 | P11: =SUMIFS('OB History'!E:E,'OB History'!B:B,A11)-O11 -> 185 | Q11: =LOOKUP(2, 1/('OB History'!$B:$B=A11), 'OB History'!$AB:$AB) -> 0.49425287 | R11: =SUMIFS('OB History'!H:H,'OB History'!B:B,'Old Bow v2'!A11) -> 734 | S11: =SUMIFS('OB History'!G:G,'OB History'!B:B,'Old Bow v2'!A11)-R11 -> 755 | T11: =LOOKUP(2, 1/('OB History'!$B:$B=A11), 'OB History'!$AC:$AC) -> 0.49356322 | U11: =COUNTIFS('OB History'!$B:$B,$A$11,'OB History'!K:K, 1) -> 17 | V11: =COUNTIFS('OB History'!$B:$B,$A$11,'OB History'!L:L, 1) -> 11 | W11: =COUNTIFS('OB History'!$B:$B,$A$11,'OB History'!M:M, 1) -> 2 | X11: =COUNTIFS('OB History'!$B:$B,$A$11,'OB History'!N:N, 1) -> 26 | Y11: =COUNTIFS('OB History'!$B:$B,$A$11,'OB History'!O:O, 1) -> 4 | Z11: =COUNTIFS('OB History'!$B:$B,$A$11,'OB History'!P:P, 1) -> 15 | AA11: =COUNTIFS('OB History'!$B:$B,$A$11,'OB History'!Q:Q, 1) -> 2 | AB11: =COUNTIFS('OB History'!$B:$B,$A$11,'OB History'!R:R, 1) -> 2 | AC11: =COUNTIFS('OB History'!$B:$B,$A$11,'OB History'!S:S, 1) -> 4 | AD11: =COUNTIFS('OB History'!$B:$B,$A$11,'OB History'!T:T, 1) -> 0 | AE11: =COUNTIFS('OB History'!$B:$B,$A$11,'OB History'!U:U, 1) -> 1 | AF11: =COUNTIFS('OB History'!$B:$B,$A$11,'OB History'!V:V, 1) -> 3 | AG11: =COUNTIFS('OB History'!$B:$B,$A$11,'OB History'!W:W, 1) -> 12 | AH11: =COUNTIFS('OB History'!$B:$B,$A$11,'OB History'!X:X, 1) -> 33 | AI11: =COUNTIFS('OB History'!$B:$B,$A$11,'OB History'!Y:Y, 1) -> 11 | AJ11: =COUNTIFS('OB History'!$B:$B,$A$11,'OB History'!Z:Z, 1) -> 32
A12: Choi | B12: 🏆 | C12: - | E12: 1 | H12: =SUMIFS('OB History'!C:C,'OB History'!B:B,A12) -> 381 | I12: =AVERAGEIFS('OB History'!C:C,'OB History'!B:B,A12) -> 15.875 | J12: {=MEDIAN(IF('OB History'!B:B=A12, 'OB History'!C:C))} -> 13 | K12: {=MAX(IF('OB History'!B:B=A12, 'OB History'!C:C))} -> 42 | L12: =COUNTIFS('OB History'!B:B,A12,'OB History'!D:D, 1) -> 11 | M12: =COUNTIFS('OB History'!B:B,A12,'OB History'!D:D, 0) -> 13 | N12: =LOOKUP(2, 1/('OB History'!$B:$B=A12), 'OB History'!$AD:$AD) -> 0.45833333 | O12: =SUMIFS('OB History'!F:F,'OB History'!B:B,A12) -> 46 | P12: =SUMIFS('OB History'!E:E,'OB History'!B:B,A12)-O12 -> 50 | Q12: =LOOKUP(2, 1/('OB History'!$B:$B=A12), 'OB History'!$AB:$AB) -> 0.47083333 | R12: =SUMIFS('OB History'!H:H,'OB History'!B:B,'Old Bow v2'!A12) -> 187 | S12: =SUMIFS('OB History'!G:G,'OB History'!B:B,'Old Bow v2'!A12)-R12 -> 209 | T12: =LOOKUP(2, 1/('OB History'!$B:$B=A12), 'OB History'!$AC:$AC) -> 0.45791667 | U12: =COUNTIFS('OB History'!$B:$B,$A$12,'OB History'!K:K, 1) -> 7 | V12: =COUNTIFS('OB History'!$B:$B,$A$12,'OB History'!L:L, 1) -> 4 | W12: =COUNTIFS('OB History'!$B:$B,$A$12,'OB History'!M:M, 1) -> 3 | X12: =COUNTIFS('OB History'!$B:$B,$A$12,'OB History'!N:N, 1) -> 4 | Y12: =COUNTIFS('OB History'!$B:$B,$A$12,'OB History'!O:O, 1) -> 1 | Z12: =COUNTIFS('OB History'!$B:$B,$A$12,'OB History'!P:P, 1) -> 1 | AA12: =COUNTIFS('OB History'!$B:$B,$A$12,'OB History'!Q:Q, 1) -> 0 | AB12: =COUNTIFS('OB History'!$B:$B,$A$12,'OB History'!R:R, 1) -> 0 | AC12: =COUNTIFS('OB History'!$B:$B,$A$12,'OB History'!S:S, 1) -> 0 | AD12: =COUNTIFS('OB History'!$B:$B,$A$12,'OB History'!T:T, 1) -> 0 | AE12: =COUNTIFS('OB History'!$B:$B,$A$12,'OB History'!U:U, 1) -> 1 | AF12: =COUNTIFS('OB History'!$B:$B,$A$12,'OB History'!V:V, 1) -> 2 | AG12: =COUNTIFS('OB History'!$B:$B,$A$12,'OB History'!W:W, 1) -> 4 | AH12: =COUNTIFS('OB History'!$B:$B,$A$12,'OB History'!X:X, 1) -> 6 | AI12: =COUNTIFS('OB History'!$B:$B,$A$12,'OB History'!Y:Y, 1) -> 6 | AJ12: =COUNTIFS('OB History'!$B:$B,$A$12,'OB History'!Z:Z, 1) -> 6
A13: Chopp | B13: - | C13: - | D13: 1 | H13: =SUMIFS('OB History'!C:C,'OB History'!B:B,A13) -> 388 | I13: =AVERAGEIFS('OB History'!C:C,'OB History'!B:B,A13) -> 18.47619 | J13: {=MEDIAN(IF('OB History'!B:B=A13, 'OB History'!C:C))} -> 16 | K13: {=MAX(IF('OB History'!B:B=A13, 'OB History'!C:C))} -> 34 | L13: =COUNTIFS('OB History'!B:B,A13,'OB History'!D:D, 1) -> 18 | M13: =COUNTIFS('OB History'!B:B,A13,'OB History'!D:D, 0) -> 3 | N13: =LOOKUP(2, 1/('OB History'!$B:$B=A13), 'OB History'!$AD:$AD) -> 0.85714286 | O13: =SUMIFS('OB History'!F:F,'OB History'!B:B,A13) -> 58 | P13: =SUMIFS('OB History'!E:E,'OB History'!B:B,A13)-O13 -> 24 | Q13: =LOOKUP(2, 1/('OB History'!$B:$B=A13), 'OB History'!$AB:$AB) -> 0.73666667 | R13: =SUMIFS('OB History'!H:H,'OB History'!B:B,'Old Bow v2'!A13) -> 200 | S13: =SUMIFS('OB History'!G:G,'OB History'!B:B,'Old Bow v2'!A13)-R13 -> 140 | T13: =LOOKUP(2, 1/('OB History'!$B:$B=A13), 'OB History'!$AC:$AC) -> 0.60190476 | U13: =COUNTIFS('OB History'!$B:$B,$A$13,'OB History'!K:K, 1) -> 5 | V13: =COUNTIFS('OB History'!$B:$B,$A$13,'OB History'!L:L, 1) -> 4 | W13: =COUNTIFS('OB History'!$B:$B,$A$13,'OB History'!M:M, 1) -> 3 | X13: =COUNTIFS('OB History'!$B:$B,$A$13,'OB History'!N:N, 1) -> 9 | Y13: =COUNTIFS('OB History'!$B:$B,$A$13,'OB History'!O:O, 1) -> 1 | Z13: =COUNTIFS('OB History'!$B:$B,$A$13,'OB History'!P:P, 1) -> 2 | AA13: =COUNTIFS('OB History'!$B:$B,$A$13,'OB History'!Q:Q, 1) -> 2 | AB13: =COUNTIFS('OB History'!$B:$B,$A$13,'OB History'!R:R, 1) -> 1 | AC13: =COUNTIFS('OB History'!$B:$B,$A$13,'OB History'!S:S, 1) -> 0 | AD13: =COUNTIFS('OB History'!$B:$B,$A$13,'OB History'!T:T, 1) -> 2 | AE13: =COUNTIFS('OB History'!$B:$B,$A$13,'OB History'!U:U, 1) -> 0 | AF13: =COUNTIFS('OB History'!$B:$B,$A$13,'OB History'!V:V, 1) -> 0 | AG13: =COUNTIFS('OB History'!$B:$B,$A$13,'OB History'!W:W, 1) -> 4 | AH13: =COUNTIFS('OB History'!$B:$B,$A$13,'OB History'!X:X, 1) -> 9 | AI13: =COUNTIFS('OB History'!$B:$B,$A$13,'OB History'!Y:Y, 1) -> 5 | AJ13: =COUNTIFS('OB History'!$B:$B,$A$13,'OB History'!Z:Z, 1) -> 11
A14: CivilAdam | B14: - | C14: - | D14: 2 | E14: 1 | H14: =SUMIFS('OB History'!C:C,'OB History'!B:B,A14) -> 871 | I14: =AVERAGEIFS('OB History'!C:C,'OB History'!B:B,A14) -> 15.836364 | J14: {=MEDIAN(IF('OB History'!B:B=A14, 'OB History'!C:C))} -> 16 | K14: {=MAX(IF('OB History'!B:B=A14, 'OB History'!C:C))} -> 34 | L14: =COUNTIFS('OB History'!B:B,A14,'OB History'!D:D, 1) -> 37 | M14: =COUNTIFS('OB History'!B:B,A14,'OB History'!D:D, 0) -> 18 | N14: =LOOKUP(2, 1/('OB History'!$B:$B=A14), 'OB History'!$AD:$AD) -> 0.67272727 | O14: =SUMIFS('OB History'!F:F,'OB History'!B:B,A14) -> 133 | P14: =SUMIFS('OB History'!E:E,'OB History'!B:B,A14)-O14 -> 91 | Q14: =LOOKUP(2, 1/('OB History'!$B:$B=A14), 'OB History'!$AB:$AB) -> 0.61272727 | R14: =SUMIFS('OB History'!H:H,'OB History'!B:B,'Old Bow v2'!A14) -> 512 | S14: =SUMIFS('OB History'!G:G,'OB History'!B:B,'Old Bow v2'!A14)-R14 -> 425 | T14: =LOOKUP(2, 1/('OB History'!$B:$B=A14), 'OB History'!$AC:$AC) -> 0.55654545 | U14: =COUNTIFS('OB History'!$B:$B,$A$14,'OB History'!K:K, 1) -> 11 | V14: =COUNTIFS('OB History'!$B:$B,$A$14,'OB History'!L:L, 1) -> 14 | W14: =COUNTIFS('OB History'!$B:$B,$A$14,'OB History'!M:M, 1) -> 2 | X14: =COUNTIFS('OB History'!$B:$B,$A$14,'OB History'!N:N, 1) -> 16 | Y14: =COUNTIFS('OB History'!$B:$B,$A$14,'OB History'!O:O, 1) -> 4 | Z14: =COUNTIFS('OB History'!$B:$B,$A$14,'OB History'!P:P, 1) -> 7 | AA14: =COUNTIFS('OB History'!$B:$B,$A$14,'OB History'!Q:Q, 1) -> 3 | AB14: =COUNTIFS('OB History'!$B:$B,$A$14,'OB History'!R:R, 1) -> 6 | AC14: =COUNTIFS('OB History'!$B:$B,$A$14,'OB History'!S:S, 1) -> 0 | AD14: =COUNTIFS('OB History'!$B:$B,$A$14,'OB History'!T:T, 1) -> 1 | AE14: =COUNTIFS('OB History'!$B:$B,$A$14,'OB History'!U:U, 1) -> 1 | AF14: =COUNTIFS('OB History'!$B:$B,$A$14,'OB History'!V:V, 1) -> 0 | AG14: =COUNTIFS('OB History'!$B:$B,$A$14,'OB History'!W:W, 1) -> 8 | AH14: =COUNTIFS('OB History'!$B:$B,$A$14,'OB History'!X:X, 1) -> 23 | AI14: =COUNTIFS('OB History'!$B:$B,$A$14,'OB History'!Y:Y, 1) -> 21 | AJ14: =COUNTIFS('OB History'!$B:$B,$A$14,'OB History'!Z:Z, 1) -> 15
A15: Crusha | B15: 🏆 | C15: - | D15: 2 | H15: =SUMIFS('OB History'!C:C,'OB History'!B:B,A15) -> 809 | I15: =AVERAGEIFS('OB History'!C:C,'OB History'!B:B,A15) -> 19.261905 | J15: {=MEDIAN(IF('OB History'!B:B=A15, 'OB History'!C:C))} -> 17.5 | K15: {=MAX(IF('OB History'!B:B=A15, 'OB History'!C:C))} -> 50 | L15: =COUNTIFS('OB History'!B:B,A15,'OB History'!D:D, 1) -> 21 | M15: =COUNTIFS('OB History'!B:B,A15,'OB History'!D:D, 0) -> 21 | N15: =LOOKUP(2, 1/('OB History'!$B:$B=A15), 'OB History'!$AD:$AD) -> 0.5 | O15: =SUMIFS('OB History'!F:F,'OB History'!B:B,A15) -> 94 | P15: =SUMIFS('OB History'!E:E,'OB History'!B:B,A15)-O15 -> 84 | Q15: =LOOKUP(2, 1/('OB History'!$B:$B=A15), 'OB History'!$AB:$AB) -> 0.54357143 | R15: =SUMIFS('OB History'!H:H,'OB History'!B:B,'Old Bow v2'!A15) -> 378 | S15: =SUMIFS('OB History'!G:G,'OB History'!B:B,'Old Bow v2'!A15)-R15 -> 361 | T15: =LOOKUP(2, 1/('OB History'!$B:$B=A15), 'OB History'!$AC:$AC) -> 0.51952381 | U15: =COUNTIFS('OB History'!$B:$B,$A$15,'OB History'!K:K, 1) -> 4 | V15: =COUNTIFS('OB History'!$B:$B,$A$15,'OB History'!L:L, 1) -> 6 | W15: =COUNTIFS('OB History'!$B:$B,$A$15,'OB History'!M:M, 1) -> 1 | X15: =COUNTIFS('OB History'!$B:$B,$A$15,'OB History'!N:N, 1) -> 10 | Y15: =COUNTIFS('OB History'!$B:$B,$A$15,'OB History'!O:O, 1) -> 1 | Z15: =COUNTIFS('OB History'!$B:$B,$A$15,'OB History'!P:P, 1) -> 8 | AA15: =COUNTIFS('OB History'!$B:$B,$A$15,'OB History'!Q:Q, 1) -> 8 | AB15: =COUNTIFS('OB History'!$B:$B,$A$15,'OB History'!R:R, 1) -> 4 | AC15: =COUNTIFS('OB History'!$B:$B,$A$15,'OB History'!S:S, 1) -> 4 | AD15: =COUNTIFS('OB History'!$B:$B,$A$15,'OB History'!T:T, 1) -> 2 | AE15: =COUNTIFS('OB History'!$B:$B,$A$15,'OB History'!U:U, 1) -> 1 | AF15: =COUNTIFS('OB History'!$B:$B,$A$15,'OB History'!V:V, 1) -> 2 | AG15: =COUNTIFS('OB History'!$B:$B,$A$15,'OB History'!W:W, 1) -> 7 | AH15: =COUNTIFS('OB History'!$B:$B,$A$15,'OB History'!X:X, 1) -> 13 | AI15: =COUNTIFS('OB History'!$B:$B,$A$15,'OB History'!Y:Y, 1) -> 11 | AJ15: =COUNTIFS('OB History'!$B:$B,$A$15,'OB History'!Z:Z, 1) -> 12
A16: DevilDuck | B16: - | C16: - | H16: =SUMIFS('OB History'!C:C,'OB History'!B:B,A16) -> 75 | I16: =AVERAGEIFS('OB History'!C:C,'OB History'!B:B,A16) -> 15 | J16: {=MEDIAN(IF('OB History'!B:B=A16, 'OB History'!C:C))} -> 14 | K16: {=MAX(IF('OB History'!B:B=A16, 'OB History'!C:C))} -> 19 | L16: =COUNTIFS('OB History'!B:B,A16,'OB History'!D:D, 1) -> 2 | M16: =COUNTIFS('OB History'!B:B,A16,'OB History'!D:D, 0) -> 3 | N16: =LOOKUP(2, 1/('OB History'!$B:$B=A16), 'OB History'!$AD:$AD) -> 0.4 | O16: =SUMIFS('OB History'!F:F,'OB History'!B:B,A16) -> 11 | P16: =SUMIFS('OB History'!E:E,'OB History'!B:B,A16)-O16 -> 11 | Q16: =LOOKUP(2, 1/('OB History'!$B:$B=A16), 'OB History'!$AB:$AB) -> 0.51 | R16: =SUMIFS('OB History'!H:H,'OB History'!B:B,'Old Bow v2'!A16) -> 50 | S16: =SUMIFS('OB History'!G:G,'OB History'!B:B,'Old Bow v2'!A16)-R16 -> 44 | T16: =LOOKUP(2, 1/('OB History'!$B:$B=A16), 'OB History'!$AC:$AC) -> 0.536 | U16: =COUNTIFS('OB History'!$B:$B,$A$16,'OB History'!K:K, 1) -> 1 | V16: =COUNTIFS('OB History'!$B:$B,$A$16,'OB History'!L:L, 1) -> 2 | W16: =COUNTIFS('OB History'!$B:$B,$A$16,'OB History'!M:M, 1) -> 0 | X16: =COUNTIFS('OB History'!$B:$B,$A$16,'OB History'!N:N, 1) -> 1 | Y16: =COUNTIFS('OB History'!$B:$B,$A$16,'OB History'!O:O, 1) -> 0 | Z16: =COUNTIFS('OB History'!$B:$B,$A$16,'OB History'!P:P, 1) -> 0 | AA16: =COUNTIFS('OB History'!$B:$B,$A$16,'OB History'!Q:Q, 1) -> 0 | AB16: =COUNTIFS('OB History'!$B:$B,$A$16,'OB History'!R:R, 1) -> 0 | AC16: =COUNTIFS('OB History'!$B:$B,$A$16,'OB History'!S:S, 1) -> 2 | AD16: =COUNTIFS('OB History'!$B:$B,$A$16,'OB History'!T:T, 1) -> 0 | AE16: =COUNTIFS('OB History'!$B:$B,$A$16,'OB History'!U:U, 1) -> 1 | AF16: =COUNTIFS('OB History'!$B:$B,$A$16,'OB History'!V:V, 1) -> 0 | AG16: =COUNTIFS('OB History'!$B:$B,$A$16,'OB History'!W:W, 1) -> 2 | AH16: =COUNTIFS('OB History'!$B:$B,$A$16,'OB History'!X:X, 1) -> 2 | AI16: =COUNTIFS('OB History'!$B:$B,$A$16,'OB History'!Y:Y, 1) -> 0 | AJ16: =COUNTIFS('OB History'!$B:$B,$A$16,'OB History'!Z:Z, 1) -> 0
A17: Dreamz | B17: 🏆 | C17: - | H17: =SUMIFS('OB History'!C:C,'OB History'!B:B,A17) -> 515 | I17: =AVERAGEIFS('OB History'!C:C,'OB History'!B:B,A17) -> 14.305556 | J17: {=MEDIAN(IF('OB History'!B:B=A17, 'OB History'!C:C))} -> 13 | K17: {=MAX(IF('OB History'!B:B=A17, 'OB History'!C:C))} -> 27 | L17: =COUNTIFS('OB History'!B:B,A17,'OB History'!D:D, 1) -> 17 | M17: =COUNTIFS('OB History'!B:B,A17,'OB History'!D:D, 0) -> 19 | N17: =LOOKUP(2, 1/('OB History'!$B:$B=A17), 'OB History'!$AD:$AD) -> 0.47222222 | O17: =SUMIFS('OB History'!F:F,'OB History'!B:B,A17) -> 72 | P17: =SUMIFS('OB History'!E:E,'OB History'!B:B,A17)-O17 -> 79 | Q17: =LOOKUP(2, 1/('OB History'!$B:$B=A17), 'OB History'!$AB:$AB) -> 0.46444444 | R17: =SUMIFS('OB History'!H:H,'OB History'!B:B,'Old Bow v2'!A17) -> 318 | S17: =SUMIFS('OB History'!G:G,'OB History'!B:B,'Old Bow v2'!A17)-R17 -> 317 | T17: =LOOKUP(2, 1/('OB History'!$B:$B=A17), 'OB History'!$AC:$AC) -> 0.49694444 | U17: =COUNTIFS('OB History'!$B:$B,$A$17,'OB History'!K:K, 1) -> 6 | V17: =COUNTIFS('OB History'!$B:$B,$A$17,'OB History'!L:L, 1) -> 6 | W17: =COUNTIFS('OB History'!$B:$B,$A$17,'OB History'!M:M, 1) -> 9 | X17: =COUNTIFS('OB History'!$B:$B,$A$17,'OB History'!N:N, 1) -> 11 | Y17: =COUNTIFS('OB History'!$B:$B,$A$17,'OB History'!O:O, 1) -> 4 | Z17: =COUNTIFS('OB History'!$B:$B,$A$17,'OB History'!P:P, 1) -> 3 | AA17: =COUNTIFS('OB History'!$B:$B,$A$17,'OB History'!Q:Q, 1) -> 2 | AB17: =COUNTIFS('OB History'!$B:$B,$A$17,'OB History'!R:R, 1) -> 2 | AC17: =COUNTIFS('OB History'!$B:$B,$A$17,'OB History'!S:S, 1) -> 0 | AD17: =COUNTIFS('OB History'!$B:$B,$A$17,'OB History'!T:T, 1) -> 0 | AE17: =COUNTIFS('OB History'!$B:$B,$A$17,'OB History'!U:U, 1) -> 0 | AF17: =COUNTIFS('OB History'!$B:$B,$A$17,'OB History'!V:V, 1) -> 1 | AG17: =COUNTIFS('OB History'!$B:$B,$A$17,'OB History'!W:W, 1) -> 3 | AH17: =COUNTIFS('OB History'!$B:$B,$A$17,'OB History'!X:X, 1) -> 10 | AI17: =COUNTIFS('OB History'!$B:$B,$A$17,'OB History'!Y:Y, 1) -> 8 | AJ17: =COUNTIFS('OB History'!$B:$B,$A$17,'OB History'!Z:Z, 1) -> 7
A18: Driver | B18: 🏆🏆🏆 | C18: - | D18: 3 | E18: 1 | H18: =SUMIFS('OB History'!C:C,'OB History'!B:B,A18) -> 850 | I18: =AVERAGEIFS('OB History'!C:C,'OB History'!B:B,A18) -> 16.037736 | J18: {=MEDIAN(IF('OB History'!B:B=A18, 'OB History'!C:C))} -> 15 | K18: {=MAX(IF('OB History'!B:B=A18, 'OB History'!C:C))} -> 44 | L18: =COUNTIFS('OB History'!B:B,A18,'OB History'!D:D, 1) -> 27 | M18: =COUNTIFS('OB History'!B:B,A18,'OB History'!D:D, 0) -> 26 | N18: =LOOKUP(2, 1/('OB History'!$B:$B=A18), 'OB History'!$AD:$AD) -> 0.50943396 | O18: =SUMIFS('OB History'!F:F,'OB History'!B:B,A18) -> 110 | P18: =SUMIFS('OB History'!E:E,'OB History'!B:B,A18)-O18 -> 111 | Q18: =LOOKUP(2, 1/('OB History'!$B:$B=A18), 'OB History'!$AB:$AB) -> 0.49301887 | R18: =SUMIFS('OB History'!H:H,'OB History'!B:B,'Old Bow v2'!A18) -> 450 | S18: =SUMIFS('OB History'!G:G,'OB History'!B:B,'Old Bow v2'!A18)-R18 -> 461 | T18: =LOOKUP(2, 1/('OB History'!$B:$B=A18), 'OB History'!$AC:$AC) -> 0.49509434 | U18: =COUNTIFS('OB History'!$B:$B,$A$18,'OB History'!K:K, 1) -> 5 | V18: =COUNTIFS('OB History'!$B:$B,$A$18,'OB History'!L:L, 1) -> 8 | W18: =COUNTIFS('OB History'!$B:$B,$A$18,'OB History'!M:M, 1) -> 4 | X18: =COUNTIFS('OB History'!$B:$B,$A$18,'OB History'!N:N, 1) -> 11 | Y18: =COUNTIFS('OB History'!$B:$B,$A$18,'OB History'!O:O, 1) -> 9 | Z18: =COUNTIFS('OB History'!$B:$B,$A$18,'OB History'!P:P, 1) -> 9 | AA18: =COUNTIFS('OB History'!$B:$B,$A$18,'OB History'!Q:Q, 1) -> 6 | AB18: =COUNTIFS('OB History'!$B:$B,$A$18,'OB History'!R:R, 1) -> 6 | AC18: =COUNTIFS('OB History'!$B:$B,$A$18,'OB History'!S:S, 1) -> 1 | AD18: =COUNTIFS('OB History'!$B:$B,$A$18,'OB History'!T:T, 1) -> 1 | AE18: =COUNTIFS('OB History'!$B:$B,$A$18,'OB History'!U:U, 1) -> 1 | AF18: =COUNTIFS('OB History'!$B:$B,$A$18,'OB History'!V:V, 1) -> 1 | AG18: =COUNTIFS('OB History'!$B:$B,$A$18,'OB History'!W:W, 1) -> 9 | AH18: =COUNTIFS('OB History'!$B:$B,$A$18,'OB History'!X:X, 1) -> 20 | AI18: =COUNTIFS('OB History'!$B:$B,$A$18,'OB History'!Y:Y, 1) -> 9 | AJ18: =COUNTIFS('OB History'!$B:$B,$A$18,'OB History'!Z:Z, 1) -> 9
A19: Engineer | B19: 🏆🏆 | C19: - | F19: 1 | H19: =SUMIFS('OB History'!C:C,'OB History'!B:B,A19) -> 891 | I19: =AVERAGEIFS('OB History'!C:C,'OB History'!B:B,A19) -> 14.606557 | J19: {=MEDIAN(IF('OB History'!B:B=A19, 'OB History'!C:C))} -> 13 | K19: {=MAX(IF('OB History'!B:B=A19, 'OB History'!C:C))} -> 41 | L19: =COUNTIFS('OB History'!B:B,A19,'OB History'!D:D, 1) -> 35 | M19: =COUNTIFS('OB History'!B:B,A19,'OB History'!D:D, 0) -> 26 | N19: =LOOKUP(2, 1/('OB History'!$B:$B=A19), 'OB History'!$AD:$AD) -> 0.57377049 | O19: =SUMIFS('OB History'!F:F,'OB History'!B:B,A19) -> 137 | P19: =SUMIFS('OB History'!E:E,'OB History'!B:B,A19)-O19 -> 113 | Q19: =LOOKUP(2, 1/('OB History'!$B:$B=A19), 'OB History'!$AB:$AB) -> 0.55868852 | R19: =SUMIFS('OB History'!H:H,'OB History'!B:B,'Old Bow v2'!A19) -> 534 | S19: =SUMIFS('OB History'!G:G,'OB History'!B:B,'Old Bow v2'!A19)-R19 -> 500 | T19: =LOOKUP(2, 1/('OB History'!$B:$B=A19), 'OB History'!$AC:$AC) -> 0.51688525 | U19: =COUNTIFS('OB History'!$B:$B,$A$19,'OB History'!K:K, 1) -> 8 | V19: =COUNTIFS('OB History'!$B:$B,$A$19,'OB History'!L:L, 1) -> 10 | W19: =COUNTIFS('OB History'!$B:$B,$A$19,'OB History'!M:M, 1) -> 6 | X19: =COUNTIFS('OB History'!$B:$B,$A$19,'OB History'!N:N, 1) -> 16 | Y19: =COUNTIFS('OB History'!$B:$B,$A$19,'OB History'!O:O, 1) -> 5 | Z19: =COUNTIFS('OB History'!$B:$B,$A$19,'OB History'!P:P, 1) -> 16 | AA19: =COUNTIFS('OB History'!$B:$B,$A$19,'OB History'!Q:Q, 1) -> 6 | AB19: =COUNTIFS('OB History'!$B:$B,$A$19,'OB History'!R:R, 1) -> 4 | AC19: =COUNTIFS('OB History'!$B:$B,$A$19,'OB History'!S:S, 1) -> 2 | AD19: =COUNTIFS('OB History'!$B:$B,$A$19,'OB History'!T:T, 1) -> 2 | AE19: =COUNTIFS('OB History'!$B:$B,$A$19,'OB History'!U:U, 1) -> 1 | AF19: =COUNTIFS('OB History'!$B:$B,$A$19,'OB History'!V:V, 1) -> 3 | AG19: =COUNTIFS('OB History'!$B:$B,$A$19,'OB History'!W:W, 1) -> 10 | AH19: =COUNTIFS('OB History'!$B:$B,$A$19,'OB History'!X:X, 1) -> 19 | AI19: =COUNTIFS('OB History'!$B:$B,$A$19,'OB History'!Y:Y, 1) -> 11 | AJ19: =COUNTIFS('OB History'!$B:$B,$A$19,'OB History'!Z:Z, 1) -> 18
A20: Erock | B20: - | C20: - | H20: =SUMIFS('OB History'!C:C,'OB History'!B:B,A20) -> 10 | I20: =AVERAGEIFS('OB History'!C:C,'OB History'!B:B,A20) -> 10 | J20: {=MEDIAN(IF('OB History'!B:B=A20, 'OB History'!C:C))} -> 10 | K20: {=MAX(IF('OB History'!B:B=A20, 'OB History'!C:C))} -> 10 | L20: =COUNTIFS('OB History'!B:B,A20,'OB History'!D:D, 1) -> 0 | M20: =COUNTIFS('OB History'!B:B,A20,'OB History'!D:D, 0) -> 1 | N20: =LOOKUP(2, 1/('OB History'!$B:$B=A20), 'OB History'!$AD:$AD) -> 0 | O20: =SUMIFS('OB History'!F:F,'OB History'!B:B,A20) -> 2 | P20: =SUMIFS('OB History'!E:E,'OB History'!B:B,A20)-O20 -> 3 | Q20: =LOOKUP(2, 1/('OB History'!$B:$B=A20), 'OB History'!$AB:$AB) -> 0.4 | R20: =SUMIFS('OB History'!H:H,'OB History'!B:B,'Old Bow v2'!A20) -> 6 | S20: =SUMIFS('OB History'!G:G,'OB History'!B:B,'Old Bow v2'!A20)-R20 -> 14 | T20: =LOOKUP(2, 1/('OB History'!$B:$B=A20), 'OB History'!$AC:$AC) -> 0.3 | U20: =COUNTIFS('OB History'!$B:$B,$A$20,'OB History'!K:K, 1) -> 0 | V20: =COUNTIFS('OB History'!$B:$B,$A$20,'OB History'!L:L, 1) -> 0 | W20: =COUNTIFS('OB History'!$B:$B,$A$20,'OB History'!M:M, 1) -> 0 | X20: =COUNTIFS('OB History'!$B:$B,$A$20,'OB History'!N:N, 1) -> 0 | Y20: =COUNTIFS('OB History'!$B:$B,$A$20,'OB History'!O:O, 1) -> 0 | Z20: =COUNTIFS('OB History'!$B:$B,$A$20,'OB History'!P:P, 1) -> 0 | AA20: =COUNTIFS('OB History'!$B:$B,$A$20,'OB History'!Q:Q, 1) -> 0 | AB20: =COUNTIFS('OB History'!$B:$B,$A$20,'OB History'!R:R, 1) -> 0 | AC20: =COUNTIFS('OB History'!$B:$B,$A$20,'OB History'!S:S, 1) -> 0 | AD20: =COUNTIFS('OB History'!$B:$B,$A$20,'OB History'!T:T, 1) -> 0 | AE20: =COUNTIFS('OB History'!$B:$B,$A$20,'OB History'!U:U, 1) -> 0 | AF20: =COUNTIFS('OB History'!$B:$B,$A$20,'OB History'!V:V, 1) -> 0 | AG20: =COUNTIFS('OB History'!$B:$B,$A$20,'OB History'!W:W, 1) -> 1 | AH20: =COUNTIFS('OB History'!$B:$B,$A$20,'OB History'!X:X, 1) -> 0 | AI20: =COUNTIFS('OB History'!$B:$B,$A$20,'OB History'!Y:Y, 1) -> 1 | AJ20: =COUNTIFS('OB History'!$B:$B,$A$20,'OB History'!Z:Z, 1) -> 0
A21: EtchV | B21: - | C21: - | H21: =SUMIFS('OB History'!C:C,'OB History'!B:B,A21) -> 294 | I21: =AVERAGEIFS('OB History'!C:C,'OB History'!B:B,A21) -> 14.7 | J21: {=MEDIAN(IF('OB History'!B:B=A21, 'OB History'!C:C))} -> 15.5 | K21: {=MAX(IF('OB History'!B:B=A21, 'OB History'!C:C))} -> 33 | L21: =COUNTIFS('OB History'!B:B,A21,'OB History'!D:D, 1) -> 8 | M21: =COUNTIFS('OB History'!B:B,A21,'OB History'!D:D, 0) -> 12 | N21: =LOOKUP(2, 1/('OB History'!$B:$B=A21), 'OB History'!$AD:$AD) -> 0.4 | O21: =SUMIFS('OB History'!F:F,'OB History'!B:B,A21) -> 32 | P21: =SUMIFS('OB History'!E:E,'OB History'!B:B,A21)-O21 -> 44 | Q21: =LOOKUP(2, 1/('OB History'!$B:$B=A21), 'OB History'!$AB:$AB) -> 0.406 | R21: =SUMIFS('OB History'!H:H,'OB History'!B:B,'Old Bow v2'!A21) -> 148 | S21: =SUMIFS('OB History'!G:G,'OB History'!B:B,'Old Bow v2'!A21)-R21 -> 174 | T21: =LOOKUP(2, 1/('OB History'!$B:$B=A21), 'OB History'!$AC:$AC) -> 0.447 | U21: =COUNTIFS('OB History'!$B:$B,$A$21,'OB History'!K:K, 1) -> 4 | V21: =COUNTIFS('OB History'!$B:$B,$A$21,'OB History'!L:L, 1) -> 3 | W21: =COUNTIFS('OB History'!$B:$B,$A$21,'OB History'!M:M, 1) -> 4 | X21: =COUNTIFS('OB History'!$B:$B,$A$21,'OB History'!N:N, 1) -> 3 | Y21: =COUNTIFS('OB History'!$B:$B,$A$21,'OB History'!O:O, 1) -> 0 | Z21: =COUNTIFS('OB History'!$B:$B,$A$21,'OB History'!P:P, 1) -> 2 | AA21: =COUNTIFS('OB History'!$B:$B,$A$21,'OB History'!Q:Q, 1) -> 3 | AB21: =COUNTIFS('OB History'!$B:$B,$A$21,'OB History'!R:R, 1) -> 1 | AC21: =COUNTIFS('OB History'!$B:$B,$A$21,'OB History'!S:S, 1) -> 0 | AD21: =COUNTIFS('OB History'!$B:$B,$A$21,'OB History'!T:T, 1) -> 0 | AE21: =COUNTIFS('OB History'!$B:$B,$A$21,'OB History'!U:U, 1) -> 0 | AF21: =COUNTIFS('OB History'!$B:$B,$A$21,'OB History'!V:V, 1) -> 0 | AG21: =COUNTIFS('OB History'!$B:$B,$A$21,'OB History'!W:W, 1) -> 1 | AH21: =COUNTIFS('OB History'!$B:$B,$A$21,'OB History'!X:X, 1) -> 7 | AI21: =COUNTIFS('OB History'!$B:$B,$A$21,'OB History'!Y:Y, 1) -> 1 | AJ21: =COUNTIFS('OB History'!$B:$B,$A$21,'OB History'!Z:Z, 1) -> 3
A22: Etho | B22: - | C22: - | H22: =SUMIFS('OB History'!C:C,'OB History'!B:B,A22) -> 0 | I22: =AVERAGEIFS('OB History'!C:C,'OB History'!B:B,A22) -> 0 | J22: {=MEDIAN(IF('OB History'!B:B=A22, 'OB History'!C:C))} -> 0 | K22: {=MAX(IF('OB History'!B:B=A22, 'OB History'!C:C))} -> 0 | L22: =COUNTIFS('OB History'!B:B,A22,'OB History'!D:D, 1) -> 0 | M22: =COUNTIFS('OB History'!B:B,A22,'OB History'!D:D, 0) -> 1 | N22: =LOOKUP(2, 1/('OB History'!$B:$B=A22), 'OB History'!$AD:$AD) -> 0 | O22: =SUMIFS('OB History'!F:F,'OB History'!B:B,A22) -> 0 | P22: =SUMIFS('OB History'!E:E,'OB History'!B:B,A22)-O22 -> 3 | Q22: =LOOKUP(2, 1/('OB History'!$B:$B=A22), 'OB History'!$AB:$AB) -> 0 | R22: =SUMIFS('OB History'!H:H,'OB History'!B:B,'Old Bow v2'!A22) -> 3 | S22: =SUMIFS('OB History'!G:G,'OB History'!B:B,'Old Bow v2'!A22)-R22 -> 9 | T22: =LOOKUP(2, 1/('OB History'!$B:$B=A22), 'OB History'!$AC:$AC) -> 0.25 | U22: =COUNTIFS('OB History'!$B:$B,$A$22,'OB History'!K:K, 1) -> 0 | V22: =COUNTIFS('OB History'!$B:$B,$A$22,'OB History'!L:L, 1) -> 0 | W22: =COUNTIFS('OB History'!$B:$B,$A$22,'OB History'!M:M, 1) -> 0 | X22: =COUNTIFS('OB History'!$B:$B,$A$22,'OB History'!N:N, 1) -> 0 | Y22: =COUNTIFS('OB History'!$B:$B,$A$22,'OB History'!O:O, 1) -> 0 | Z22: =COUNTIFS('OB History'!$B:$B,$A$22,'OB History'!P:P, 1) -> 0 | AA22: =COUNTIFS('OB History'!$B:$B,$A$22,'OB History'!Q:Q, 1) -> 0 | AB22: =COUNTIFS('OB History'!$B:$B,$A$22,'OB History'!R:R, 1) -> 0 | AC22: =COUNTIFS('OB History'!$B:$B,$A$22,'OB History'!S:S, 1) -> 0 | AD22: =COUNTIFS('OB History'!$B:$B,$A$22,'OB History'!T:T, 1) -> 0 | AE22: =COUNTIFS('OB History'!$B:$B,$A$22,'OB History'!U:U, 1) -> 0 | AF22: =COUNTIFS('OB History'!$B:$B,$A$22,'OB History'!V:V, 1) -> 0 | AG22: =COUNTIFS('OB History'!$B:$B,$A$22,'OB History'!W:W, 1) -> 0 | AH22: =COUNTIFS('OB History'!$B:$B,$A$22,'OB History'!X:X, 1) -> 0 | AI22: =COUNTIFS('OB History'!$B:$B,$A$22,'OB History'!Y:Y, 1) -> 0 | AJ22: =COUNTIFS('OB History'!$B:$B,$A$22,'OB History'!Z:Z, 1) -> 0
A23: Faded | B23: - | C23: - | H23: =SUMIFS('OB History'!C:C,'OB History'!B:B,A23) -> 11 | I23: =AVERAGEIFS('OB History'!C:C,'OB History'!B:B,A23) -> 2.75 | J23: {=MEDIAN(IF('OB History'!B:B=A23, 'OB History'!C:C))} -> 1.5 | K23: {=MAX(IF('OB History'!B:B=A23, 'OB History'!C:C))} -> 8 | L23: =COUNTIFS('OB History'!B:B,A23,'OB History'!D:D, 1) -> 4 | M23: =COUNTIFS('OB History'!B:B,A23,'OB History'!D:D, 0) -> 0 | N23: =LOOKUP(2, 1/('OB History'!$B:$B=A23), 'OB History'!$AD:$AD) -> 1 | O23: =SUMIFS('OB History'!F:F,'OB History'!B:B,A23) -> 12 | P23: =SUMIFS('OB History'!E:E,'OB History'!B:B,A23)-O23 -> 4 | Q23: =LOOKUP(2, 1/('OB History'!$B:$B=A23), 'OB History'!$AB:$AB) -> 0.775 | R23: =SUMIFS('OB History'!H:H,'OB History'!B:B,'Old Bow v2'!A23) -> 39 | S23: =SUMIFS('OB History'!G:G,'OB History'!B:B,'Old Bow v2'!A23)-R23 -> 24 | T23: =LOOKUP(2, 1/('OB History'!$B:$B=A23), 'OB History'!$AC:$AC) -> 0.6325 | U23: =COUNTIFS('OB History'!$B:$B,$A$23,'OB History'!K:K, 1) -> 1 | V23: =COUNTIFS('OB History'!$B:$B,$A$23,'OB History'!L:L, 1) -> 2 | W23: =COUNTIFS('OB History'!$B:$B,$A$23,'OB History'!M:M, 1) -> 0 | X23: =COUNTIFS('OB History'!$B:$B,$A$23,'OB History'!N:N, 1) -> 3 | Y23: =COUNTIFS('OB History'!$B:$B,$A$23,'OB History'!O:O, 1) -> 0 | Z23: =COUNTIFS('OB History'!$B:$B,$A$23,'OB History'!P:P, 1) -> 0 | AA23: =COUNTIFS('OB History'!$B:$B,$A$23,'OB History'!Q:Q, 1) -> 1 | AB23: =COUNTIFS('OB History'!$B:$B,$A$23,'OB History'!R:R, 1) -> 1 | AC23: =COUNTIFS('OB History'!$B:$B,$A$23,'OB History'!S:S, 1) -> 0 | AD23: =COUNTIFS('OB History'!$B:$B,$A$23,'OB History'!T:T, 1) -> 0 | AE23: =COUNTIFS('OB History'!$B:$B,$A$23,'OB History'!U:U, 1) -> 0 | AF23: =COUNTIFS('OB History'!$B:$B,$A$23,'OB History'!V:V, 1) -> 0 | AG23: =COUNTIFS('OB History'!$B:$B,$A$23,'OB History'!W:W, 1) -> 0 | AH23: =COUNTIFS('OB History'!$B:$B,$A$23,'OB History'!X:X, 1) -> 1 | AI23: =COUNTIFS('OB History'!$B:$B,$A$23,'OB History'!Y:Y, 1) -> 2 | AJ23: =COUNTIFS('OB History'!$B:$B,$A$23,'OB History'!Z:Z, 1) -> 1
A24: FlyinRyan | B24: 🏆 | C24: - | H24: =SUMIFS('OB History'!C:C,'OB History'!B:B,A24) -> 321 | I24: =AVERAGEIFS('OB History'!C:C,'OB History'!B:B,A24) -> 13.375 | J24: {=MEDIAN(IF('OB History'!B:B=A24, 'OB History'!C:C))} -> 12.5 | K24: {=MAX(IF('OB History'!B:B=A24, 'OB History'!C:C))} -> 29 | L24: =COUNTIFS('OB History'!B:B,A24,'OB History'!D:D, 1) -> 9 | M24: =COUNTIFS('OB History'!B:B,A24,'OB History'!D:D, 0) -> 15 | N24: =LOOKUP(2, 1/('OB History'!$B:$B=A24), 'OB History'!$AD:$AD) -> 0.375 | O24: =SUMIFS('OB History'!F:F,'OB History'!B:B,A24) -> 47 | P24: =SUMIFS('OB History'!E:E,'OB History'!B:B,A24)-O24 -> 56 | Q24: =LOOKUP(2, 1/('OB History'!$B:$B=A24), 'OB History'!$AB:$AB) -> 0.45208333 | R24: =SUMIFS('OB History'!H:H,'OB History'!B:B,'Old Bow v2'!A24) -> 201 | S24: =SUMIFS('OB History'!G:G,'OB History'!B:B,'Old Bow v2'!A24)-R24 -> 216 | T24: =LOOKUP(2, 1/('OB History'!$B:$B=A24), 'OB History'!$AC:$AC) -> 0.48208333 | U24: =COUNTIFS('OB History'!$B:$B,$A$24,'OB History'!K:K, 1) -> 1 | V24: =COUNTIFS('OB History'!$B:$B,$A$24,'OB History'!L:L, 1) -> 3 | W24: =COUNTIFS('OB History'!$B:$B,$A$24,'OB History'!M:M, 1) -> 2 | X24: =COUNTIFS('OB History'!$B:$B,$A$24,'OB History'!N:N, 1) -> 7 | Y24: =COUNTIFS('OB History'!$B:$B,$A$24,'OB History'!O:O, 1) -> 0 | Z24: =COUNTIFS('OB History'!$B:$B,$A$24,'OB History'!P:P, 1) -> 6 | AA24: =COUNTIFS('OB History'!$B:$B,$A$24,'OB History'!Q:Q, 1) -> 0 | AB24: =COUNTIFS('OB History'!$B:$B,$A$24,'OB History'!R:R, 1) -> 1 | AC24: =COUNTIFS('OB History'!$B:$B,$A$24,'OB History'!S:S, 1) -> 1 | AD24: =COUNTIFS('OB History'!$B:$B,$A$24,'OB History'!T:T, 1) -> 1 | AE24: =COUNTIFS('OB History'!$B:$B,$A$24,'OB History'!U:U, 1) -> 0 | AF24: =COUNTIFS('OB History'!$B:$B,$A$24,'OB History'!V:V, 1) -> 0 | AG24: =COUNTIFS('OB History'!$B:$B,$A$24,'OB History'!W:W, 1) -> 3 | AH24: =COUNTIFS('OB History'!$B:$B,$A$24,'OB History'!X:X, 1) -> 8 | AI24: =COUNTIFS('OB History'!$B:$B,$A$24,'OB History'!Y:Y, 1) -> 6 | AJ24: =COUNTIFS('OB History'!$B:$B,$A$24,'OB History'!Z:Z, 1) -> 8
A25: Focus | B25: - | C25: - | H25: =SUMIFS('OB History'!C:C,'OB History'!B:B,A25) -> 97 | I25: =AVERAGEIFS('OB History'!C:C,'OB History'!B:B,A25) -> 12.125 | J25: {=MEDIAN(IF('OB History'!B:B=A25, 'OB History'!C:C))} -> 12.5 | K25: {=MAX(IF('OB History'!B:B=A25, 'OB History'!C:C))} -> 17 | L25: =COUNTIFS('OB History'!B:B,A25,'OB History'!D:D, 1) -> 2 | M25: =COUNTIFS('OB History'!B:B,A25,'OB History'!D:D, 0) -> 6 | N25: =LOOKUP(2, 1/('OB History'!$B:$B=A25), 'OB History'!$AD:$AD) -> 0.25 | O25: =SUMIFS('OB History'!F:F,'OB History'!B:B,A25) -> 13 | P25: =SUMIFS('OB History'!E:E,'OB History'!B:B,A25)-O25 -> 19 | Q25: =LOOKUP(2, 1/('OB History'!$B:$B=A25), 'OB History'!$AB:$AB) -> 0.425 | R25: =SUMIFS('OB History'!H:H,'OB History'!B:B,'Old Bow v2'!A25) -> 64 | S25: =SUMIFS('OB History'!G:G,'OB History'!B:B,'Old Bow v2'!A25)-R25 -> 72 | T25: =LOOKUP(2, 1/('OB History'!$B:$B=A25), 'OB History'!$AC:$AC) -> 0.4775 | U25: =COUNTIFS('OB History'!$B:$B,$A$25,'OB History'!K:K, 1) -> 1 | V25: =COUNTIFS('OB History'!$B:$B,$A$25,'OB History'!L:L, 1) -> 1 | W25: =COUNTIFS('OB History'!$B:$B,$A$25,'OB History'!M:M, 1) -> 1 | X25: =COUNTIFS('OB History'!$B:$B,$A$25,'OB History'!N:N, 1) -> 2 | Y25: =COUNTIFS('OB History'!$B:$B,$A$25,'OB History'!O:O, 1) -> 0 | Z25: =COUNTIFS('OB History'!$B:$B,$A$25,'OB History'!P:P, 1) -> 2 | AA25: =COUNTIFS('OB History'!$B:$B,$A$25,'OB History'!Q:Q, 1) -> 0 | AB25: =COUNTIFS('OB History'!$B:$B,$A$25,'OB History'!R:R, 1) -> 2 | AC25: =COUNTIFS('OB History'!$B:$B,$A$25,'OB History'!S:S, 1) -> 1 | AD25: =COUNTIFS('OB History'!$B:$B,$A$25,'OB History'!T:T, 1) -> 0 | AE25: =COUNTIFS('OB History'!$B:$B,$A$25,'OB History'!U:U, 1) -> 0 | AF25: =COUNTIFS('OB History'!$B:$B,$A$25,'OB History'!V:V, 1) -> 0 | AG25: =COUNTIFS('OB History'!$B:$B,$A$25,'OB History'!W:W, 1) -> 1 | AH25: =COUNTIFS('OB History'!$B:$B,$A$25,'OB History'!X:X, 1) -> 1 | AI25: =COUNTIFS('OB History'!$B:$B,$A$25,'OB History'!Y:Y, 1) -> 1 | AJ25: =COUNTIFS('OB History'!$B:$B,$A$25,'OB History'!Z:Z, 1) -> 0
A26: Fox | B26: - | C26: - | H26: =SUMIFS('OB History'!C:C,'OB History'!B:B,A26) -> 111 | I26: =AVERAGEIFS('OB History'!C:C,'OB History'!B:B,A26) -> 13.875 | J26: {=MEDIAN(IF('OB History'!B:B=A26, 'OB History'!C:C))} -> 10.5 | K26: {=MAX(IF('OB History'!B:B=A26, 'OB History'!C:C))} -> 34 | L26: =COUNTIFS('OB History'!B:B,A26,'OB History'!D:D, 1) -> 3 | M26: =COUNTIFS('OB History'!B:B,A26,'OB History'!D:D, 0) -> 5 | N26: =LOOKUP(2, 1/('OB History'!$B:$B=A26), 'OB History'!$AD:$AD) -> 0.375 | O26: =SUMIFS('OB History'!F:F,'OB History'!B:B,A26) -> 12 | P26: =SUMIFS('OB History'!E:E,'OB History'!B:B,A26)-O26 -> 19 | Q26: =LOOKUP(2, 1/('OB History'!$B:$B=A26), 'OB History'!$AB:$AB) -> 0.34375 | R26: =SUMIFS('OB History'!H:H,'OB History'!B:B,'Old Bow v2'!A26) -> 54 | S26: =SUMIFS('OB History'!G:G,'OB History'!B:B,'Old Bow v2'!A26)-R26 -> 77 | T26: =LOOKUP(2, 1/('OB History'!$B:$B=A26), 'OB History'!$AC:$AC) -> 0.3975 | U26: =COUNTIFS('OB History'!$B:$B,$A$26,'OB History'!K:K, 1) -> 0 | V26: =COUNTIFS('OB History'!$B:$B,$A$26,'OB History'!L:L, 1) -> 1 | W26: =COUNTIFS('OB History'!$B:$B,$A$26,'OB History'!M:M, 1) -> 1 | X26: =COUNTIFS('OB History'!$B:$B,$A$26,'OB History'!N:N, 1) -> 1 | Y26: =COUNTIFS('OB History'!$B:$B,$A$26,'OB History'!O:O, 1) -> 1 | Z26: =COUNTIFS('OB History'!$B:$B,$A$26,'OB History'!P:P, 1) -> 1 | AA26: =COUNTIFS('OB History'!$B:$B,$A$26,'OB History'!Q:Q, 1) -> 0 | AB26: =COUNTIFS('OB History'!$B:$B,$A$26,'OB History'!R:R, 1) -> 1 | AC26: =COUNTIFS('OB History'!$B:$B,$A$26,'OB History'!S:S, 1) -> 0 | AD26: =COUNTIFS('OB History'!$B:$B,$A$26,'OB History'!T:T, 1) -> 1 | AE26: =COUNTIFS('OB History'!$B:$B,$A$26,'OB History'!U:U, 1) -> 0 | AF26: =COUNTIFS('OB History'!$B:$B,$A$26,'OB History'!V:V, 1) -> 0 | AG26: =COUNTIFS('OB History'!$B:$B,$A$26,'OB History'!W:W, 1) -> 1 | AH26: =COUNTIFS('OB History'!$B:$B,$A$26,'OB History'!X:X, 1) -> 3 | AI26: =COUNTIFS('OB History'!$B:$B,$A$26,'OB History'!Y:Y, 1) -> 1 | AJ26: =COUNTIFS('OB History'!$B:$B,$A$26,'OB History'!Z:Z, 1) -> 0
A27: Frag N Clear | B27: - | C27: - | D27: 2 | H27: =SUMIFS('OB History'!C:C,'OB History'!B:B,A27) -> 249 | I27: =AVERAGEIFS('OB History'!C:C,'OB History'!B:B,A27) -> 16.6 | J27: {=MEDIAN(IF('OB History'!B:B=A27, 'OB History'!C:C))} -> 17 | K27: {=MAX(IF('OB History'!B:B=A27, 'OB History'!C:C))} -> 28 | L27: =COUNTIFS('OB History'!B:B,A27,'OB History'!D:D, 1) -> 13 | M27: =COUNTIFS('OB History'!B:B,A27,'OB History'!D:D, 0) -> 2 | N27: =LOOKUP(2, 1/('OB History'!$B:$B=A27), 'OB History'!$AD:$AD) -> 0.86666667 | O27: =SUMIFS('OB History'!F:F,'OB History'!B:B,A27) -> 40 | P27: =SUMIFS('OB History'!E:E,'OB History'!B:B,A27)-O27 -> 18 | Q27: =LOOKUP(2, 1/('OB History'!$B:$B=A27), 'OB History'!$AB:$AB) -> 0.71 | R27: =SUMIFS('OB History'!H:H,'OB History'!B:B,'Old Bow v2'!A27) -> 140 | S27: =SUMIFS('OB History'!G:G,'OB History'!B:B,'Old Bow v2'!A27)-R27 -> 96 | T27: =LOOKUP(2, 1/('OB History'!$B:$B=A27), 'OB History'!$AC:$AC) -> 0.60266667 | U27: =COUNTIFS('OB History'!$B:$B,$A$27,'OB History'!K:K, 1) -> 4 | V27: =COUNTIFS('OB History'!$B:$B,$A$27,'OB History'!L:L, 1) -> 4 | W27: =COUNTIFS('OB History'!$B:$B,$A$27,'OB History'!M:M, 1) -> 3 | X27: =COUNTIFS('OB History'!$B:$B,$A$27,'OB History'!N:N, 1) -> 2 | Y27: =COUNTIFS('OB History'!$B:$B,$A$27,'OB History'!O:O, 1) -> 0 | Z27: =COUNTIFS('OB History'!$B:$B,$A$27,'OB History'!P:P, 1) -> 3 | AA27: =COUNTIFS('OB History'!$B:$B,$A$27,'OB History'!Q:Q, 1) -> 1 | AB27: =COUNTIFS('OB History'!$B:$B,$A$27,'OB History'!R:R, 1) -> 1 | AC27: =COUNTIFS('OB History'!$B:$B,$A$27,'OB History'!S:S, 1) -> 1 | AD27: =COUNTIFS('OB History'!$B:$B,$A$27,'OB History'!T:T, 1) -> 0 | AE27: =COUNTIFS('OB History'!$B:$B,$A$27,'OB History'!U:U, 1) -> 0 | AF27: =COUNTIFS('OB History'!$B:$B,$A$27,'OB History'!V:V, 1) -> 0 | AG27: =COUNTIFS('OB History'!$B:$B,$A$27,'OB History'!W:W, 1) -> 3 | AH27: =COUNTIFS('OB History'!$B:$B,$A$27,'OB History'!X:X, 1) -> 8 | AI27: =COUNTIFS('OB History'!$B:$B,$A$27,'OB History'!Y:Y, 1) -> 5 | AJ27: =COUNTIFS('OB History'!$B:$B,$A$27,'OB History'!Z:Z, 1) -> 5
A28: Hopes | B28: 🏆🏆🏆 | C28: - | D28: 4 | E28: 1 | H28: =SUMIFS('OB History'!C:C,'OB History'!B:B,A28) -> 812 | I28: =AVERAGEIFS('OB History'!C:C,'OB History'!B:B,A28) -> 26.193548 | J28: {=MEDIAN(IF('OB History'!B:B=A28, 'OB History'!C:C))} -> 26 | K28: {=MAX(IF('OB History'!B:B=A28, 'OB History'!C:C))} -> 48 | L28: =COUNTIFS('OB History'!B:B,A28,'OB History'!D:D, 1) -> 19 | M28: =COUNTIFS('OB History'!B:B,A28,'OB History'!D:D, 0) -> 12 | N28: =LOOKUP(2, 1/('OB History'!$B:$B=A28), 'OB History'!$AD:$AD) -> 0.61290323 | O28: =SUMIFS('OB History'!F:F,'OB History'!B:B,A28) -> 66 | P28: =SUMIFS('OB History'!E:E,'OB History'!B:B,A28)-O28 -> 62 | Q28: =LOOKUP(2, 1/('OB History'!$B:$B=A28), 'OB History'!$AB:$AB) -> 0.5016129 | R28: =SUMIFS('OB History'!H:H,'OB History'!B:B,'Old Bow v2'!A28) -> 252 | S28: =SUMIFS('OB History'!G:G,'OB History'!B:B,'Old Bow v2'!A28)-R28 -> 261 | T28: =LOOKUP(2, 1/('OB History'!$B:$B=A28), 'OB History'!$AC:$AC) -> 0.47935484 | U28: =COUNTIFS('OB History'!$B:$B,$A$28,'OB History'!K:K, 1) -> 4 | V28: =COUNTIFS('OB History'!$B:$B,$A$28,'OB History'!L:L, 1) -> 6 | W28: =COUNTIFS('OB History'!$B:$B,$A$28,'OB History'!M:M, 1) -> 5 | X28: =COUNTIFS('OB History'!$B:$B,$A$28,'OB History'!N:N, 1) -> 3 | Y28: =COUNTIFS('OB History'!$B:$B,$A$28,'OB History'!O:O, 1) -> 9 | Z28: =COUNTIFS('OB History'!$B:$B,$A$28,'OB History'!P:P, 1) -> 5 | AA28: =COUNTIFS('OB History'!$B:$B,$A$28,'OB History'!Q:Q, 1) -> 0 | AB28: =COUNTIFS('OB History'!$B:$B,$A$28,'OB History'!R:R, 1) -> 2 | AC28: =COUNTIFS('OB History'!$B:$B,$A$28,'OB History'!S:S, 1) -> 0 | AD28: =COUNTIFS('OB History'!$B:$B,$A$28,'OB History'!T:T, 1) -> 0 | AE28: =COUNTIFS('OB History'!$B:$B,$A$28,'OB History'!U:U, 1) -> 0 | AF28: =COUNTIFS('OB History'!$B:$B,$A$28,'OB History'!V:V, 1) -> 0 | AG28: =COUNTIFS('OB History'!$B:$B,$A$28,'OB History'!W:W, 1) -> 5 | AH28: =COUNTIFS('OB History'!$B:$B,$A$28,'OB History'!X:X, 1) -> 10 | AI28: =COUNTIFS('OB History'!$B:$B,$A$28,'OB History'!Y:Y, 1) -> 9 | AJ28: =COUNTIFS('OB History'!$B:$B,$A$28,'OB History'!Z:Z, 1) -> 8
A29: StevO | B29: 🏆 | C29: - | D29: 4 | H29: =SUMIFS('OB History'!C:C,'OB History'!B:B,A29) -> 1101 | I29: =AVERAGEIFS('OB History'!C:C,'OB History'!B:B,A29) -> 21.173077 | J29: {=MEDIAN(IF('OB History'!B:B=A29, 'OB History'!C:C))} -> 21 | K29: {=MAX(IF('OB History'!B:B=A29, 'OB History'!C:C))} -> 41 | L29: =COUNTIFS('OB History'!B:B,A29,'OB History'!D:D, 1) -> 29 | M29: =COUNTIFS('OB History'!B:B,A29,'OB History'!D:D, 0) -> 23 | N29: =LOOKUP(2, 1/('OB History'!$B:$B=A29), 'OB History'!$AD:$AD) -> 0.55769231 | O29: =SUMIFS('OB History'!F:F,'OB History'!B:B,A29) -> 110 | P29: =SUMIFS('OB History'!E:E,'OB History'!B:B,A29)-O29 -> 98 | Q29: =LOOKUP(2, 1/('OB History'!$B:$B=A29), 'OB History'!$AB:$AB) -> 0.535 | R29: =SUMIFS('OB History'!H:H,'OB History'!B:B,'Old Bow v2'!A29) -> 449 | S29: =SUMIFS('OB History'!G:G,'OB History'!B:B,'Old Bow v2'!A29)-R29 -> 405 | T29: =LOOKUP(2, 1/('OB History'!$B:$B=A29), 'OB History'!$AC:$AC) -> 0.52826923 | U29: =COUNTIFS('OB History'!$B:$B,$A$29,'OB History'!K:K, 1) -> 9 | V29: =COUNTIFS('OB History'!$B:$B,$A$29,'OB History'!L:L, 1) -> 6 | W29: =COUNTIFS('OB History'!$B:$B,$A$29,'OB History'!M:M, 1) -> 4 | X29: =COUNTIFS('OB History'!$B:$B,$A$29,'OB History'!N:N, 1) -> 15 | Y29: =COUNTIFS('OB History'!$B:$B,$A$29,'OB History'!O:O, 1) -> 0 | Z29: =COUNTIFS('OB History'!$B:$B,$A$29,'OB History'!P:P, 1) -> 7 | AA29: =COUNTIFS('OB History'!$B:$B,$A$29,'OB History'!Q:Q, 1) -> 7 | AB29: =COUNTIFS('OB History'!$B:$B,$A$29,'OB History'!R:R, 1) -> 3 | AC29: =COUNTIFS('OB History'!$B:$B,$A$29,'OB History'!S:S, 1) -> 3 | AD29: =COUNTIFS('OB History'!$B:$B,$A$29,'OB History'!T:T, 1) -> 1 | AE29: =COUNTIFS('OB History'!$B:$B,$A$29,'OB History'!U:U, 1) -> 2 | AF29: =COUNTIFS('OB History'!$B:$B,$A$29,'OB History'!V:V, 1) -> 0 | AG29: =COUNTIFS('OB History'!$B:$B,$A$29,'OB History'!W:W, 1) -> 7 | AH29: =COUNTIFS('OB History'!$B:$B,$A$29,'OB History'!X:X, 1) -> 16 | AI29: =COUNTIFS('OB History'!$B:$B,$A$29,'OB History'!Y:Y, 1) -> 17 | AJ29: =COUNTIFS('OB History'!$B:$B,$A$29,'OB History'!Z:Z, 1) -> 13
A30: Itch | B30: 🏆🏆🏆🏆 | C30: - | D30: 2 | H30: =SUMIFS('OB History'!C:C,'OB History'!B:B,A30) -> 1205 | I30: =AVERAGEIFS('OB History'!C:C,'OB History'!B:B,A30) -> 11.586538 | J30: {=MEDIAN(IF('OB History'!B:B=A30, 'OB History'!C:C))} -> 12 | K30: {=MAX(IF('OB History'!B:B=A30, 'OB History'!C:C))} -> 22 | L30: =COUNTIFS('OB History'!B:B,A30,'OB History'!D:D, 1) -> 46 | M30: =COUNTIFS('OB History'!B:B,A30,'OB History'!D:D, 0) -> 58 | N30: =LOOKUP(2, 1/('OB History'!$B:$B=A30), 'OB History'!$AD:$AD) -> 0.44230769 | O30: =SUMIFS('OB History'!F:F,'OB History'!B:B,A30) -> 205 | P30: =SUMIFS('OB History'!E:E,'OB History'!B:B,A30)-O30 -> 226 | Q30: =LOOKUP(2, 1/('OB History'!$B:$B=A30), 'OB History'!$AB:$AB) -> 0.47067308 | R30: =SUMIFS('OB History'!H:H,'OB History'!B:B,'Old Bow v2'!A30) -> 876 | S30: =SUMIFS('OB History'!G:G,'OB History'!B:B,'Old Bow v2'!A30)-R30 -> 919 | T30: =LOOKUP(2, 1/('OB History'!$B:$B=A30), 'OB History'!$AC:$AC) -> 0.48778846 | U30: =COUNTIFS('OB History'!$B:$B,$A$30,'OB History'!K:K, 1) -> 15 | V30: =COUNTIFS('OB History'!$B:$B,$A$30,'OB History'!L:L, 1) -> 19 | W30: =COUNTIFS('OB History'!$B:$B,$A$30,'OB History'!M:M, 1) -> 4 | X30: =COUNTIFS('OB History'!$B:$B,$A$30,'OB History'!N:N, 1) -> 25 | Y30: =COUNTIFS('OB History'!$B:$B,$A$30,'OB History'!O:O, 1) -> 8 | Z30: =COUNTIFS('OB History'!$B:$B,$A$30,'OB History'!P:P, 1) -> 12 | AA30: =COUNTIFS('OB History'!$B:$B,$A$30,'OB History'!Q:Q, 1) -> 4 | AB30: =COUNTIFS('OB History'!$B:$B,$A$30,'OB History'!R:R, 1) -> 4 | AC30: =COUNTIFS('OB History'!$B:$B,$A$30,'OB History'!S:S, 1) -> 1 | AD30: =COUNTIFS('OB History'!$B:$B,$A$30,'OB History'!T:T, 1) -> 1 | AE30: =COUNTIFS('OB History'!$B:$B,$A$30,'OB History'!U:U, 1) -> 1 | AF30: =COUNTIFS('OB History'!$B:$B,$A$30,'OB History'!V:V, 1) -> 3 | AG30: =COUNTIFS('OB History'!$B:$B,$A$30,'OB History'!W:W, 1) -> 20 | AH30: =COUNTIFS('OB History'!$B:$B,$A$30,'OB History'!X:X, 1) -> 39 | AI30: =COUNTIFS('OB History'!$B:$B,$A$30,'OB History'!Y:Y, 1) -> 26 | AJ30: =COUNTIFS('OB History'!$B:$B,$A$30,'OB History'!Z:Z, 1) -> 22
